Workbook

Sheet Resumen
A1: Planificación de clases virtuales: Sistemas Biomecatrónicos (14 semanas)
A2: ESPOL, VIRTUAL PAO 2 2026. Cada sesión dura 105 minutos y sigue la estructura antes, durante y después. Nivel de Bloom predominante = el de mayor peso de la sesión.
A4: Semana | B4: Tema de la sesión | C4: Nivel de Bloom predominante | D4: Duración (min)
A5: Semana 1 | B5: Introducción a los sistemas biomecatrónicos | C5: Comprender | D5: ='Semana 1'!B5
A6: Semana 2 | B6: Introducción a machine learning | C6: Comprender | D6: ='Semana 2'!B5
A7: Semana 3 | B7: Machine learning supervisado y no supervisado | C7: Analizar | D7: ='Semana 3'!B5
A8: Semana 4 | B8: Algoritmos de ML en biomedicina: clasificación, regresión y modelos no supervisados | C8: Aplicar | D8: ='Semana 4'!B5
A9: Semana 5 | B9: Práctica con señales biomédicas: EMG y EEG | C9: Aplicar | D9: ='Semana 5'!B5
A10: Semana 6 | B10: Práctica con señales biomédicas: ECG (EKG) y PPG | C10: Aplicar | D10: ='Semana 6'!B5
A11: Semana 7 | B11: Imágenes médicas: rayos X, TAC, ecografía, resonancia magnética y PET | C11: Analizar | D11: ='Semana 7'!B5
A12: Semana 8 | B12: Introducción al deep learning y a las redes neuronales | C12: Comprender | D12: ='Semana 8'!B5
A13: Semana 9 | B13: Redes neuronales aplicadas a señales biomédicas | C13: Aplicar | D13: ='Semana 9'!B5
A14: Semana 10 | B14: Redes neuronales convolucionales (CNN) | C14: Comprender | D14: ='Semana 10'!B5
A15: Semana 11 | B15: Clasificación de tumores y patologías con redes convolucionales | C15: Evaluar | D15: ='Semana 11'!B5
A16: Semana 12 | B16: Segmentación de tumores cerebrales con la arquitectura U-Net | C16: Aplicar | D16: ='Semana 12'!B5
A17: Semana 13 | B17: Biomecánica del movimiento y esfuerzos de tensión y compresión en huesos | C17: Aplicar | D17: ='Semana 13'!B5
A18: Semana 14 | B18: Análisis por elementos finitos del fémur y cierre del curso | C18: Crear | D18: ='Semana 14'!B5
C19: Total del curso (min) | D19: =SUM(D5:D18)
A21: Estructura de cada pestaña
A22: 1. Objetivos por nivel de Bloom: recordar, comprender, aplicar, analizar, evaluar, crear.
A23: 2. ANTES: trabajo asincrónico previo con lecturas, datasets y preparación de herramientas.
A24: 3. DURANTE: 105 minutos divididos en 7 pasos con hora de inicio y fin calculadas.
A25: 4. DESPUÉS: entregables y consolidación.
A26: Los tiempos en azul son datos editables; el resto son fórmulas.
A28: Supuesto de organización
A29: Los 14 temas del curso caben en 14 sesiones agrupando EMG con EEG en la semana 5 y ECG con PPG en la semana 6, y uniendo tensión y compresión de huesos con la biomecánica del movimiento en la semana 13. Ajustar si el sílabo oficial indica otra distribución.

Sheet Semana 1
A1: Semana 1: Introducción a los sistemas biomecatrónicos
A2: Sistemas Biomecatrónicos, ESPOL. Clase virtual sincrónica de 1 h 45 min (105 min). Organización por taxonomía de Bloom revisada.
A4: Resultado de aprendizaje | B4: Describe los componentes de un sistema biomecatrónico (sensores, procesamiento, control, actuadores e interfaz biológica) y explica su papel en la ingeniería biomédica.
A5: Duración total (min) | B5: =D33
A6: Control de tiempo | B6: =IF(D33=105,"Correcto: 105 min","Revisar: no suma 105 min")
A8: 1. Objetivos por nivel de la taxonomía de Bloom
A9: Nivel | E9: Verbo de acción | F9: Objetivo de aprendizaje | G9: Evidencia
A10: 1. Recordar | E10: Enumerar/Definir | F10: Enumerar los subsistemas de un sistema biomecatrónico y dos aplicaciones clínicas de cada uno. | G10: Quiz de 5 preguntas en Google Forms
A11: 2. Comprender | E11: Explicar | F11: Explicar cómo se integran biología, mecánica, electrónica y control en una prótesis o un exoesqueleto. | G11: Explicación breve en foro o mapa conceptual
A12: 3. Aplicar | E12: Aplicar/Ejecutar | F12: Clasificar dispositivos reales (prótesis mioeléctrica, exoesqueleto, marcapasos) según sensores, actuadores y control. | G12: Notebook o ejercicio resuelto en clase
A13: 4. Analizar | E13: Analizar/Comparar | F13: Analizar el flujo señal biológica, procesamiento y actuación en un caso de estudio. | G13: Comparación de resultados o casos en sala virtual
A14: 5. Evaluar | E14: Evaluar/Justificar | F14: Valorar ventajas, riesgos y aspectos éticos de un dispositivo biomecatrónico. | G14: Rúbrica de coevaluación de la plenaria
A15: 6. Crear | E15: Diseñar/Proponer | F15: Proponer un diagrama de bloques para una necesidad clínica concreta. | G15: Entregable o mini propuesta posterior a la clase
A17: 2. ANTES de la clase (trabajo asincrónico, 48 horas previas)
A18: Ítem | D18: Min | E18: Nivel Bloom | F18: Actividad | G18: Entregable | H18: Enlace verificado
A19: A1 | D19: 15 | E19: Recordar | F19: Leer el sílabo, la planificación y las rúbricas del curso en el aula virtual. (Aula virtual ESPOL) | G19: Confirmar lectura en el foro de bienvenida
A20: A2 | D20: 25 | E20: Comprender | F20: Leer el artículo de introducción a la biomecatrónica y anotar tres términos nuevos. (Lectura) | G20: Tres términos con su definición | H20: https://en.wikipedia.org/wiki/Biomechatronics
A21: A3 | D21: 30 | E21: Comprender | F21: Revisar la revisión sobre biomimética y biomecatrónica y elegir un dispositivo de interés. (Lectura) | G21: Nombre del dispositivo elegido | H21: https://pmc.ncbi.nlm.nih.gov/articles/PMC9326577/
C22: Total | D22: =SUM(D19:D21)
A24: 3. DURANTE la clase (105 min, paso a paso)
A25: Paso | B25: Inicio (min) | C25: Fin (min) | D25: Min | E25: Fase / Nivel Bloom | F25: Actividad paso a paso | G25: Herramienta | H25: Enlace verificado
A26: 1 | B26: 0 | C26: =B26+D26 | D26: 10 | E26: Apertura (Recordar) | F26: Bienvenida, reglas de participación virtual (cámara, chat, micrófono), sílabo, evaluación y niveles de la taxonomía de Bloom usados en el curso. Sondeo inicial: ¿qué dispositivo biomecatrónico conoces? | G26: Zoom o Teams, chat | H26: https://derekbruff.org/vanderbilt-cft-teaching-guides-archive/blooms-taxonomy/
A27: 2 | B27: =C26 | C27: =B27+D27 | D27: 20 | E27: Exposición (Comprender) | F27: Presentar la arquitectura general: sensor, acondicionamiento, controlador, actuador, interfaz con el cuerpo. Mostrar el diagrama de bloques con ejemplos (prótesis, exoesqueleto, marcapasos). | G27: Zoom, presentación | H27: https://en.wikipedia.org/wiki/Biomechatronics
A28: 3 | B28: =C27 | C28: =B28+D28 | D28: 20 | E28: Demostración en vivo (Aplicar) | F28: Compartir pantalla y recorrer paso a paso una prótesis mioeléctrica: electrodos, amplificación, decisión, movimiento del actuador. Los estudiantes señalan cada bloque en el chat. | G28: Zoom, Colab o software | H28: https://en.wikipedia.org/wiki/Biomechatronics
A29: 4 | B29: =C28 | C29: =B29+D29 | D29: 5 | E29: Pausa | F29: Pausa de 5 minutos: apagar cámara, estirarse, volver puntuales. | G29: Cronómetro visible
A30: 5 | B30: =C29 | C30: =B30+D30 | D30: 25 | E30: Práctica en salas virtuales (Analizar) | F30: Salas de 4 personas: cada grupo completa una tabla con tres dispositivos (sensores, actuadores, control, señal biológica) en un documento compartido de Google. | G30: Salas de Zoom, Google Docs | H30: https://pmc.ncbi.nlm.nih.gov/articles/PMC9326577/
A31: 6 | B31: =C30 | C31: =B31+D31 | D31: 15 | E31: Plenaria y discusión (Evaluar) | F31: Cada grupo presenta una fila de su tabla. Discusión guiada: riesgos, seguridad del paciente y ética del uso de estos dispositivos. | G31: Zoom, rúbrica
A32: 7 | B32: =C31 | C32: =B32+D32 | D32: 10 | E32: Cierre y evaluación (Crear) | F32: Quiz de 5 preguntas en Google Forms, explicación de la tarea y adelanto de la semana 2 (introducción a machine learning). | G32: Google Forms, aula virtual
C33: Total | D33: =SUM(D26:D32)
A35: 4. DESPUÉS de la clase (trabajo asincrónico)
A36: Ítem | D36: Min | E36: Nivel Bloom | F36: Actividad | G36: Entregable | H36: Enlace verificado
A37: D1 | D37: 45 | E37: Crear | F37: Dibujar el diagrama de bloques de un dispositivo biomecatrónico para una necesidad clínica (una página). (Entregable individual en el aula virtual) | G37: Diagrama con bloques y señales rotuladas
A38: D2 | D38: 20 | E38: Evaluar | F38: Escribir en el foro un párrafo sobre un riesgo ético del dispositivo elegido y responder a un compañero. (Foro del aula virtual) | G38: Un aporte y una respuesta
A39: D3 | D39: 15 | E39: Aplicar | F39: Crear una cuenta en Google Colab y abrir el cuaderno de bienvenida. (Google Colab) | G39: Captura de pantalla de la cuenta activa | H39: https://colab.research.google.com/
C40: Total | D40: =SUM(D37:D39)

Sheet Semana 2
A1: Semana 2: Introducción a machine learning
A2: Sistemas Biomecatrónicos, ESPOL. Clase virtual sincrónica de 1 h 45 min (105 min). Organización por taxonomía de Bloom revisada.
A4: Resultado de aprendizaje | B4: Explica qué es machine learning, sus tipos y el flujo de trabajo (datos, entrenamiento, validación y prueba) con ejemplos biomédicos.
A5: Duración total (min) | B5: =D33
A6: Control de tiempo | B6: =IF(D33=105,"Correcto: 105 min","Revisar: no suma 105 min")
A8: 1. Objetivos por nivel de la taxonomía de Bloom
A9: Nivel | E9: Verbo de acción | F9: Objetivo de aprendizaje | G9: Evidencia
A10: 1. Recordar | E10: Enumerar/Definir | F10: Definir aprendizaje automático, característica, etiqueta, modelo y función de pérdida. | G10: Quiz de 5 preguntas en Google Forms
A11: 2. Comprender | E11: Explicar | F11: Explicar la diferencia entre programación clásica y aprendizaje a partir de datos. | G11: Explicación breve en foro o mapa conceptual
A12: 3. Aplicar | E12: Aplicar/Ejecutar | F12: Ejecutar en Colab la división entrenamiento/prueba de un conjunto de datos pequeño. | G12: Notebook o ejercicio resuelto en clase
A13: 4. Analizar | E13: Analizar/Comparar | F13: Analizar por qué un modelo puede sobreajustar usando las curvas de entrenamiento y validación. | G13: Comparación de resultados o casos en sala virtual
A14: 5. Evaluar | E14: Evaluar/Justificar | F14: Valorar si un problema biomédico es adecuado para machine learning según los datos disponibles. | G14: Rúbrica de coevaluación de la plenaria
A15: 6. Crear | E15: Diseñar/Proponer | F15: Diseñar el flujo de trabajo de ML para un problema clínico propuesto. | G15: Entregable o mini propuesta posterior a la clase
A17: 2. ANTES de la clase (trabajo asincrónico, 48 horas previas)
A18: Ítem | D18: Min | E18: Nivel Bloom | F18: Actividad | G18: Entregable | H18: Enlace verificado
A19: A1 | D19: 40 | E19: Comprender | F19: Cursar el módulo de introducción de Machine Learning Crash Course. (Curso en línea) | G19: Resumen de cinco líneas | H19: https://developers.google.com/machine-learning/crash-course
A20: A2 | D20: 15 | E20: Aplicar | F20: Abrir Colab y ejecutar la primera celda de código de práctica. (Google Colab) | G20: Captura de la celda ejecutada | H20: https://colab.research.google.com/
A21: A3 | D21: 10 | E21: Recordar | F21: Responder el formulario diagnóstico de conocimientos previos de Python. (Google Forms) | G21: Formulario enviado
C22: Total | D22: =SUM(D19:D21)
A24: 3. DURANTE la clase (105 min, paso a paso)
A25: Paso | B25: Inicio (min) | C25: Fin (min) | D25: Min | E25: Fase / Nivel Bloom | F25: Actividad paso a paso | G25: Herramienta | H25: Enlace verificado
A26: 1 | B26: 0 | C26: =B26+D26 | D26: 10 | E26: Apertura (Recordar) | F26: Repaso de la semana 1 con dos preguntas orales. Objetivos de la sesión y agenda de 105 minutos. | G26: Zoom o Teams, chat
A27: 2 | B27: =C26 | C27: =B27+D27 | D27: 20 | E27: Exposición (Comprender) | F27: Exposición: qué es ML, tipos de aprendizaje, flujo de trabajo, ejemplos en biomedicina (diagnóstico por imagen, señales fisiológicas, predicción de riesgo). | G27: Zoom, presentación | H27: https://developers.google.com/machine-learning/crash-course
A28: 3 | B28: =C27 | C28: =B28+D28 | D28: 20 | E28: Demostración en vivo (Aplicar) | F28: Demostración en Colab: cargar un conjunto de datos tabular, separar entrenamiento y prueba, entrenar un modelo simple y medir su exactitud. | G28: Zoom, Colab o software | H28: https://colab.research.google.com/ https://scikit-learn.org/stable/user_guide.html
A29: 4 | B29: =C28 | C29: =B29+D29 | D29: 5 | E29: Pausa | F29: Pausa de 5 minutos. | G29: Cronómetro visible
A30: 5 | B30: =C29 | C30: =B30+D30 | D30: 25 | E30: Práctica en salas virtuales (Analizar) | F30: Salas de 4 personas: para tres casos biomédicos, identificar entrada, salida, tipo de problema y riesgo de sobreajuste. Registrar en un documento compartido. | G30: Salas de Zoom, Google Docs
A31: 6 | B31: =C30 | C31: =B31+D31 | D31: 15 | E31: Plenaria y discusión (Evaluar) | F31: Plenaria: cada sala defiende un caso. Discusión sobre calidad de datos, sesgo y privacidad del paciente. | G31: Zoom, rúbrica
A32: 7 | B32: =C31 | C32: =B32+D32 | D32: 10 | E32: Cierre y evaluación (Crear) | F32: Quiz en Google Forms, publicación de la tarea y adelanto de la semana 3 (aprendizaje supervisado y no supervisado). | G32: Google Forms, aula virtual
C33: Total | D33: =SUM(D26:D32)
A35: 4. DESPUÉS de la clase (trabajo asincrónico)
A36: Ítem | D36: Min | E36: Nivel Bloom | F36: Actividad | G36: Entregable | H36: Enlace verificado
A37: D1 | D37: 40 | E37: Aplicar | F37: Completar el cuaderno de la clase con una partición 70/30 y reportar la exactitud. (Google Colab) | G37: Cuaderno compartido con permiso de lectura | H37: https://colab.research.google.com/
A38: D2 | D38: 30 | E38: Crear | F38: Escribir media página sobre un problema clínico de la carrera que podría resolverse con ML y qué datos harían falta. (Aula virtual) | G38: Texto de media página
A39: D3 | D39: 20 | E39: Comprender | F39: Leer la sección de scikit-learn sobre validación para la próxima clase. (Guía de usuario) | G39: Tres dudas anotadas | H39: https://scikit-learn.org/stable/user_guide.html
C40: Total | D40: =SUM(D37:D39)

Sheet Semana 3
A1: Semana 3: Machine learning supervisado y no supervisado
A2: Sistemas Biomecatrónicos, ESPOL. Clase virtual sincrónica de 1 h 45 min (105 min). Organización por taxonomía de Bloom revisada.
A4: Resultado de aprendizaje | B4: Distingue el aprendizaje supervisado del no supervisado y selecciona el tipo de algoritmo adecuado según el problema y los datos.
A5: Duración total (min) | B5: =D33
A6: Control de tiempo | B6: =IF(D33=105,"Correcto: 105 min","Revisar: no suma 105 min")
A8: 1. Objetivos por nivel de la taxonomía de Bloom
A9: Nivel | E9: Verbo de acción | F9: Objetivo de aprendizaje | G9: Evidencia
A10: 1. Recordar | E10: Enumerar/Definir | F10: Nombrar los algoritmos supervisados y no supervisados más usados (regresión lineal, k-vecinos, árboles, k-means). | G10: Quiz de 5 preguntas en Google Forms
A11: 2. Comprender | E11: Explicar | F11: Explicar cuándo se usa clasificación, regresión y agrupamiento. | G11: Explicación breve en foro o mapa conceptual
A12: 3. Aplicar | E12: Aplicar/Ejecutar | F12: Entrenar en Colab un clasificador supervisado y un modelo k-means sobre el mismo conjunto de datos. | G12: Notebook o ejercicio resuelto en clase
A13: 4. Analizar | E13: Analizar/Comparar | F13: Comparar resultados de ambos enfoques con métricas apropiadas (exactitud, inercia, silueta). | G13: Comparación de resultados o casos en sala virtual
A14: 5. Evaluar | E14: Evaluar/Justificar | F14: Justificar la elección de un algoritmo para un caso biomédico dado. | G14: Rúbrica de coevaluación de la plenaria
A15: 6. Crear | E15: Diseñar/Proponer | F15: Diseñar un experimento que combine un paso no supervisado y uno supervisado. | G15: Entregable o mini propuesta posterior a la clase
A17: 2. ANTES de la clase (trabajo asincrónico, 48 horas previas)
A18: Ítem | D18: Min | E18: Nivel Bloom | F18: Actividad | G18: Entregable | H18: Enlace verificado
A19: A1 | D19: 30 | E19: Comprender | F19: Leer la sección de aprendizaje supervisado de la guía de scikit-learn (regresión lineal y k-vecinos). (Guía de usuario) | G19: Tabla de dos algoritmos con ventajas | H19: https://scikit-learn.org/stable/user_guide.html
A20: A2 | D20: 20 | E20: Comprender | F20: Leer la sección de clustering y ubicar k-means. (Guía de usuario) | G20: Definición propia de k-means | H20: https://scikit-learn.org/stable/modules/clustering.html
A21: A3 | D21: 20 | E21: Aplicar | F21: Repetir el cuaderno de la semana 2 con un conjunto de datos distinto. (Google Colab) | G21: Cuaderno ejecutado | H21: https://colab.research.google.com/
C22: Total | D22: =SUM(D19:D21)
A24: 3. DURANTE la clase (105 min, paso a paso)
A25: Paso | B25: Inicio (min) | C25: Fin (min) | D25: Min | E25: Fase / Nivel Bloom | F25: Actividad paso a paso | G25: Herramienta | H25: Enlace verificado
A26: 1 | B26: 0 | C26: =B26+D26 | D26: 10 | E26: Apertura (Recordar) | F26: Repaso de la semana 2, resolución de dudas de la tarea y agenda de la sesión. | G26: Zoom o Teams, chat
A27: 2 | B27: =C26 | C27: =B27+D27 | D27: 20 | E27: Exposición (Comprender) | F27: Exposición: aprendizaje supervisado (clasificación y regresión) frente a no supervisado (agrupamiento y reducción de dimensión). Métricas de cada uno. | G27: Zoom, presentación | H27: https://scikit-learn.org/stable/user_guide.html
A28: 3 | B28: =C27 | C28: =B28+D28 | D28: 20 | E28: Demostración en vivo (Aplicar) | F28: Demostración en Colab: entrenar k-vecinos y k-means con el mismo conjunto de datos y visualizar fronteras y grupos. | G28: Zoom, Colab o software | H28: https://colab.research.google.com/ https://scikit-learn.org/stable/modules/clustering.html
A29: 4 | B29: =C28 | C29: =B29+D29 | D29: 5 | E29: Pausa | F29: Pausa de 5 minutos. | G29: Cronómetro visible
A30: 5 | B30: =C29 | C30: =B30+D30 | D30: 25 | E30: Práctica en salas virtuales (Analizar) | F30: Salas de 4 personas: modificar el número de vecinos y de grupos, registrar cómo cambian las métricas y explicar la causa. | G30: Salas de Zoom, Google Docs | H30: https://scikit-learn.org/stable/user_guide.html
A31: 6 | B31: =C30 | C31: =B31+D31 | D31: 15 | E31: Plenaria y discusión (Evaluar) | F31: Plenaria: cada sala expone un hallazgo. Discusión sobre cuándo no hay etiquetas disponibles en un hospital. | G31: Zoom, rúbrica
A32: 7 | B32: =C31 | C32: =B32+D32 | D32: 10 | E32: Cierre y evaluación (Crear) | F32: Quiz en Google Forms, publicación de la tarea y adelanto de la semana 4 (algoritmos aplicados a biomedicina). | G32: Google Forms, aula virtual
C33: Total | D33: =SUM(D26:D32)
A35: 4. DESPUÉS de la clase (trabajo asincrónico)
A36: Ítem | D36: Min | E36: Nivel Bloom | F36: Actividad | G36: Entregable | H36: Enlace verificado
A37: D1 | D37: 35 | E37: Analizar | F37: Elaborar una tabla comparativa de cuatro algoritmos (tipo, entrada, salida, métrica, riesgo). (Documento de Google) | G37: Tabla completa
A38: D2 | D38: 40 | E38: Crear | F38: Redactar el diseño de un experimento con un paso no supervisado seguido de uno supervisado. (Aula virtual) | G38: Diseño de una página | H38: https://scikit-learn.org/stable/user_guide.html
A39: D3 | D39: 10 | E39: Evaluar | F39: Autoevaluación con el formulario de la unidad. (Google Forms) | G39: Puntaje registrado
C40: Total | D40: =SUM(D37:D39)

Sheet Semana 4
A1: Semana 4: Algoritmos de ML en biomedicina: clasificación, regresión y modelos no supervisados
A2: Sistemas Biomecatrónicos, ESPOL. Clase virtual sincrónica de 1 h 45 min (105 min). Organización por taxonomía de Bloom revisada.
A4: Resultado de aprendizaje | B4: Aplica algoritmos de clasificación, regresión y agrupamiento a un conjunto de datos biomédico y evalúa su desempeño.
A5: Duración total (min) | B5: =D33
A6: Control de tiempo | B6: =IF(D33=105,"Correcto: 105 min","Revisar: no suma 105 min")
A8: 1. Objetivos por nivel de la taxonomía de Bloom
A9: Nivel | E9: Verbo de acción | F9: Objetivo de aprendizaje | G9: Evidencia
A10: 1. Recordar | E10: Enumerar/Definir | F10: Recordar las métricas de clasificación (exactitud, sensibilidad, especificidad) y de regresión (MAE, RMSE, R2). | G10: Quiz de 5 preguntas en Google Forms
A11: 2. Comprender | E11: Explicar | F11: Explicar por qué la sensibilidad y la especificidad importan más que la exactitud en diagnóstico. | G11: Explicación breve en foro o mapa conceptual
A12: 3. Aplicar | E12: Aplicar/Ejecutar | F12: Entrenar un clasificador sobre el conjunto de EMG de miembro inferior para distinguir rodillas sanas de anormales. | G12: Notebook o ejercicio resuelto en clase
A13: 4. Analizar | E13: Analizar/Comparar | F13: Analizar la matriz de confusión e identificar el tipo de error más costoso clínicamente. | G13: Comparación de resultados o casos en sala virtual
A14: 5. Evaluar | E14: Evaluar/Justificar | F14: Evaluar el modelo con validación cruzada y decidir si es aceptable para uso clínico. | G14: Rúbrica de coevaluación de la plenaria
A15: 6. Crear | E15: Diseñar/Proponer | F15: Proponer una mejora al modelo (nuevas características o algoritmo) y justificarla. | G15: Entregable o mini propuesta posterior a la clase
A17: 2. ANTES de la clase (trabajo asincrónico, 48 horas previas)
A18: Ítem | D18: Min | E18: Nivel Bloom | F18: Actividad | G18: Entregable | H18: Enlace verificado
A19: A1 | D19: 25 | E19: Comprender | F19: Leer la descripción del conjunto de EMG de miembro inferior y anotar las variables. (Conjunto de datos) | G19: Lista de variables | H19: https://archive.ics.uci.edu/dataset/278/emg+dataset+in+lower+limb
A20: A2 | D20: 30 | E20: Comprender | F20: Leer la sección de evaluación de modelos de la guía de scikit-learn. (Guía de usuario) | G20: Definición de sensibilidad y especificidad | H20: https://scikit-learn.org/stable/user_guide.html
A21: A3 | D21: 20 | E21: Aplicar | F21: Descargar el conjunto de datos y cargarlo en Colab. (Google Colab) | G21: Tabla cargada en el cuaderno | H21: https://colab.research.google.com/
C22: Total | D22: =SUM(D19:D21)
A24: 3. DURANTE la clase (105 min, paso a paso)
A25: Paso | B25: Inicio (min) | C25: Fin (min) | D25: Min | E25: Fase / Nivel Bloom | F25: Actividad paso a paso | G25: Herramienta | H25: Enlace verificado
A26: 1 | B26: 0 | C26: =B26+D26 | D26: 10 | E26: Apertura (Recordar) | F26: Repaso de métricas y de la tarea de la semana 3. Presentar el objetivo: clasificar y predecir con datos de EMG y goniometría. | G26: Zoom o Teams, chat | H26: https://scikit-learn.org/stable/user_guide.html
A27: 2 | B27: =C26 | C27: =B27+D27 | D27: 20 | E27: Exposición (Comprender) | F27: Exposición: clasificación (regresión logística, árboles, k-vecinos), regresión (lineal, aleatoria) y agrupamiento aplicados a biomedicina. Pipeline y validación cruzada. | G27: Zoom, presentación | H27: https://scikit-learn.org/stable/user_guide.html https://scikit-learn.org/stable/modules/clustering.html
A28: 3 | B28: =C27 | C28: =B28+D28 | D28: 20 | E28: Demostración en vivo (Aplicar) | F28: Demostración en Colab: entrenar un clasificador, calcular la matriz de confusión y una regresión del ángulo de la rodilla. | G28: Zoom, Colab o software | H28: https://colab.research.google.com/ https://archive.ics.uci.edu/dataset/278/emg+dataset+in+lower+limb
A29: 4 | B29: =C28 | C29: =B29+D29 | D29: 5 | E29: Pausa | F29: Pausa de 5 minutos. | G29: Cronómetro visible
A30: 5 | B30: =C29 | C30: =B30+D30 | D30: 25 | E30: Práctica en salas virtuales (Analizar) | F30: Salas de 4 personas: probar dos algoritmos, comparar métricas y decidir cuál es más seguro para el paciente. | G30: Salas de Zoom, Google Docs | H30: https://archive.ics.uci.edu/dataset/278/emg+dataset+in+lower+limb
A31: 6 | B31: =C30 | C31: =B31+D31 | D31: 15 | E31: Plenaria y discusión (Evaluar) | F31: Plenaria: cada sala justifica su elección. Discusión sobre falsos negativos en diagnóstico y sobre el tamaño pequeño del conjunto de datos. | G31: Zoom, rúbrica
A32: 7 | B32: =C31 | C32: =B32+D32 | D32: 10 | E32: Cierre y evaluación (Crear) | F32: Quiz en Google Forms, publicación de la tarea y adelanto de la semana 5 (señales EMG y EEG). | G32: Google Forms, aula virtual
C33: Total | D33: =SUM(D26:D32)
A35: 4. DESPUÉS de la clase (trabajo asincrónico)
A36: Ítem | D36: Min | E36: Nivel Bloom | F36: Actividad | G36: Entregable | H36: Enlace verificado
A37: D1 | D37: 50 | E37: Aplicar | F37: Entregar el cuaderno con clasificación, regresión y agrupamiento, cada uno con su métrica. (Google Colab) | G37: Cuaderno con conclusiones | H37: https://colab.research.google.com/
A38: D2 | D38: 20 | E38: Evaluar | F38: Redactar un párrafo que justifique qué algoritmo recomendarías y por qué. (Aula virtual) | G38: Párrafo de justificación
A39: D3 | D39: 15 | E39: Crear | F39: Proponer una característica adicional que mejore el modelo. (Foro) | G39: Propuesta en el foro
C40: Total | D40: =SUM(D37:D39)

Sheet Semana 5
A1: Semana 5: Práctica con señales biomédicas: EMG y EEG
A2: Sistemas Biomecatrónicos, ESPOL. Clase virtual sincrónica de 1 h 45 min (105 min). Organización por taxonomía de Bloom revisada.
A4: Resultado de aprendizaje | B4: Preprocesa señales EMG y EEG, extrae características y entrena un clasificador sencillo con ellas.
A5: Duración total (min) | B5: =D33
A6: Control de tiempo | B6: =IF(D33=105,"Correcto: 105 min","Revisar: no suma 105 min")
A8: 1. Objetivos por nivel de la taxonomía de Bloom
A9: Nivel | E9: Verbo de acción | F9: Objetivo de aprendizaje | G9: Evidencia
A10: 1. Recordar | E10: Enumerar/Definir | F10: Recordar el origen fisiológico de la EMG y del EEG y sus bandas de frecuencia típicas. | G10: Quiz de 5 preguntas en Google Forms
A11: 2. Comprender | E11: Explicar | F11: Explicar por qué se filtra la señal y qué hace un filtro pasa banda. | G11: Explicación breve en foro o mapa conceptual
A12: 3. Aplicar | E12: Aplicar/Ejecutar | F12: Aplicar filtrado y ventaneo a un registro y calcular RMS de EMG y potencia por banda de EEG. | G12: Notebook o ejercicio resuelto en clase
A13: 4. Analizar | E13: Analizar/Comparar | F13: Analizar cómo cambian las características entre reposo y movimiento (o ojos abiertos y cerrados). | G13: Comparación de resultados o casos en sala virtual
A14: 5. Evaluar | E14: Evaluar/Justificar | F14: Evaluar la calidad de la señal e identificar artefactos. | G14: Rúbrica de coevaluación de la plenaria
A15: 6. Crear | E15: Diseñar/Proponer | F15: Crear un pipeline completo: señal, filtro, características y clasificador. | G15: Entregable o mini propuesta posterior a la clase
A17: 2. ANTES de la clase (trabajo asincrónico, 48 horas previas)
A18: Ítem | D18: Min | E18: Nivel Bloom | F18: Actividad | G18: Entregable | H18: Enlace verificado
A19: A1 | D19: 35 | E19: Comprender | F19: Leer el artículo de NeuroKit2 y la introducción de MNE-Python sobre análisis EEG. (Lectura) | G19: Glosario de cinco términos | H19: https://link.springer.com/article/10.3758/s13428-020-01516-y https://mne.tools/stable/auto_tutorials/intro/10_overview.html
A20: A2 | D20: 20 | E20: Recordar | F20: Explorar el conjunto de EEG de movimiento e imaginación motora y ubicar los archivos. (Conjunto de datos) | G20: Lista de tareas registradas | H20: https://physionet.org/content/eegmmidb/1.0.0/
A21: A3 | D21: 15 | E21: Aplicar | F21: Instalar NeuroKit2 y MNE en Colab. (Google Colab) | G21: Instalación exitosa | H21: https://colab.research.google.com/ https://pypi.org/project/neurokit2/
C22: Total | D22: =SUM(D19:D21)
A24: 3. DURANTE la clase (105 min, paso a paso)
A25: Paso | B25: Inicio (min) | C25: Fin (min) | D25: Min | E25: Fase / Nivel Bloom | F25: Actividad paso a paso | G25: Herramienta | H25: Enlace verificado
A26: 1 | B26: 0 | C26: =B26+D26 | D26: 10 | E26: Apertura (Recordar) | F26: Repaso de métricas y objetivos. Recordar la ética del manejo de datos fisiológicos. | G26: Zoom o Teams, chat
A27: 2 | B27: =C26 | C27: =B27+D27 | D27: 20 | E27: Exposición (Comprender) | F27: Exposición: adquisición y características de EMG y EEG, ruido y artefactos, filtros, ventaneo y características (RMS, MAV, bandas alfa y beta). | G27: Zoom, presentación | H27: https://link.springer.com/article/10.3758/s13428-020-01516-y
A28: 3 | B28: =C27 | C28: =B28+D28 | D28: 20 | E28: Demostración en vivo (Aplicar) | F28: Demostración en Colab: cargar un registro, filtrar, graficar y extraer características con NeuroKit2 y MNE. | G28: Zoom, Colab o software | H28: https://colab.research.google.com/ https://pypi.org/project/neurokit2/ https://mne.tools/stable/auto_tutorials/intro/10_overview.html
A29: 4 | B29: =C28 | C29: =B29+D29 | D29: 5 | E29: Pausa | F29: Pausa de 5 minutos. | G29: Cronómetro visible
A30: 5 | B30: =C29 | C30: =B30+D30 | D30: 25 | E30: Práctica en salas virtuales (Analizar) | F30: Salas de 4 personas: extraer características de dos condiciones distintas y entrenar un clasificador simple. Comparar resultados. | G30: Salas de Zoom, Google Docs | H30: https://physionet.org/content/eegmmidb/1.0.0/ https://archive.ics.uci.edu/dataset/278/emg+dataset+in+lower+limb
A31: 6 | B31: =C30 | C31: =B31+D31 | D31: 15 | E31: Plenaria y discusión (Evaluar) | F31: Plenaria: cada sala muestra su gráfica y su métrica. Discusión sobre artefactos oculares, cardiacos y de movimiento. | G31: Zoom, rúbrica
A32: 7 | B32: =C31 | C32: =B32+D32 | D32: 10 | E32: Cierre y evaluación (Crear) | F32: Quiz en Google Forms, publicación de la tarea y adelanto de la semana 6 (ECG y PPG). | G32: Google Forms, aula virtual
C33: Total | D33: =SUM(D26:D32)
A35: 4. DESPUÉS de la clase (trabajo asincrónico)
A36: Ítem | D36: Min | E36: Nivel Bloom | F36: Actividad | G36: Entregable | H36: Enlace verificado
A37: D1 | D37: 45 | E37: Aplicar | F37: Completar el cuaderno de la clase con una segunda condición y reportar exactitud. (Google Colab) | G37: Cuaderno ejecutado | H37: https://colab.research.google.com/
A38: D2 | D38: 25 | E38: Analizar | F38: Redactar qué artefactos aparecieron y cómo los mitigarías. (Aula virtual) | G38: Texto de media página | H38: https://mne.tools/stable/auto_tutorials/intro/10_overview.html
A39: D3 | D39: 25 | E39: Crear | F39: Proponer un pipeline de control para una prótesis basado en EMG. (Documento de Google) | G39: Diagrama y descripción | H39: https://archive.ics.uci.edu/dataset/278/emg+dataset+in+lower+limb
C40: Total | D40: =SUM(D37:D39)

Sheet Semana 6
A1: Semana 6: Práctica con señales biomédicas: ECG (EKG) y PPG
A2: Sistemas Biomecatrónicos, ESPOL. Clase virtual sincrónica de 1 h 45 min (105 min). Organización por taxonomía de Bloom revisada.
A4: Resultado de aprendizaje | B4: Detecta picos R y pulsos, calcula frecuencia cardiaca y variabilidad, y clasifica latidos con características extraídas de ECG y PPG.
A5: Duración total (min) | B5: =D33
A6: Control de tiempo | B6: =IF(D33=105,"Correcto: 105 min","Revisar: no suma 105 min")
A8: 1. Objetivos por nivel de la taxonomía de Bloom
A9: Nivel | E9: Verbo de acción | F9: Objetivo de aprendizaje | G9: Evidencia
A10: 1. Recordar | E10: Enumerar/Definir | F10: Recordar las ondas P, QRS y T del ECG y la forma de un pulso de PPG. | G10: Quiz de 5 preguntas en Google Forms
A11: 2. Comprender | E11: Explicar | F11: Explicar cómo se obtiene la frecuencia cardiaca desde ECG y desde PPG. | G11: Explicación breve en foro o mapa conceptual
A12: 3. Aplicar | E12: Aplicar/Ejecutar | F12: Aplicar detección de picos R y de pulsos con NeuroKit2 sobre registros de PhysioNet. | G12: Notebook o ejercicio resuelto en clase
A13: 4. Analizar | E13: Analizar/Comparar | F13: Analizar diferencias entre latidos normales y arrítmicos usando características de intervalo. | G13: Comparación de resultados o casos en sala virtual
A14: 5. Evaluar | E14: Evaluar/Justificar | F14: Evaluar la concordancia entre la frecuencia cardiaca del ECG y la del PPG. | G14: Rúbrica de coevaluación de la plenaria
A15: 6. Crear | E15: Diseñar/Proponer | F15: Crear un clasificador de latidos con características de RR. | G15: Entregable o mini propuesta posterior a la clase
A17: 2. ANTES de la clase (trabajo asincrónico, 48 horas previas)
A18: Ítem | D18: Min | E18: Nivel Bloom | F18: Actividad | G18: Entregable | H18: Enlace verificado
A19: A1 | D19: 25 | E19: Comprender | F19: Ver la descripción del conjunto MIT-BIH y anotar las clases de latidos. (Conjunto de datos) | G19: Lista de clases de latidos | H19: https://physionet.org/content/mitdb/1.0.0/
A20: A2 | D20: 20 | E20: Comprender | F20: Revisar la descripción del conjunto BIDMC con ECG, PPG y respiración. (Conjunto de datos) | G20: Frecuencia de muestreo y duración | H20: https://physionet.org/content/bidmc/1.0.0/
A21: A3 | D21: 25 | E21: Aplicar | F21: Instalar NeuroKit2 en Colab y ejecutar el ejemplo de ECG. (Google Colab) | G21: Gráfica del ECG con picos | H21: https://colab.research.google.com/ https://pypi.org/project/neurokit2/
C22: Total | D22: =SUM(D19:D21)
A24: 3. DURANTE la clase (105 min, paso a paso)
A25: Paso | B25: Inicio (min) | C25: Fin (min) | D25: Min | E25: Fase / Nivel Bloom | F25: Actividad paso a paso | G25: Herramienta | H25: Enlace verificado
A26: 1 | B26: 0 | C26: =B26+D26 | D26: 10 | E26: Apertura (Recordar) | F26: Repaso de EMG y EEG, y del pipeline de señal. Objetivos de la sesión. | G26: Zoom o Teams, chat
A27: 2 | B27: =C26 | C27: =B27+D27 | D27: 20 | E27: Exposición (Comprender) | F27: Exposición: anatomía del ECG, forma del pulso de PPG, intervalos RR, frecuencia cardiaca y variabilidad. Arritmias frecuentes. | G27: Zoom, presentación | H27: https://physionet.org/content/mitdb/1.0.0/ https://physionet.org/content/bidmc/1.0.0/
A28: 3 | B28: =C27 | C28: =B28+D28 | D28: 20 | E28: Demostración en vivo (Aplicar) | F28: Demostración en Colab: leer un registro de PhysioNet, detectar picos R y pulsos y calcular frecuencia cardiaca. | G28: Zoom, Colab o software | H28: https://colab.research.google.com/ https://pypi.org/project/neurokit2/
A29: 4 | B29: =C28 | C29: =B29+D29 | D29: 5 | E29: Pausa | F29: Pausa de 5 minutos. | G29: Cronómetro visible
A30: 5 | B30: =C29 | C30: =B30+D30 | D30: 25 | E30: Práctica en salas virtuales (Analizar) | F30: Salas de 4 personas: comparar la frecuencia cardiaca de ECG y PPG y clasificar latidos con características de RR. | G30: Salas de Zoom, Google Docs | H30: https://physionet.org/content/mitdb/1.0.0/ https://physionet.org/content/bidmc/1.0.0/
A31: 6 | B31: =C30 | C31: =B31+D31 | D31: 15 | E31: Plenaria y discusión (Evaluar) | F31: Plenaria: cada sala presenta su comparación. Discusión sobre limitaciones del PPG en movimiento y con perfusión baja. | G31: Zoom, rúbrica
A32: 7 | B32: =C31 | C32: =B32+D32 | D32: 10 | E32: Cierre y evaluación (Crear) | F32: Quiz en Google Forms, publicación de la tarea y adelanto de la semana 7 (imágenes médicas). | G32: Google Forms, aula virtual
C33: Total | D33: =SUM(D26:D32)
A35: 4. DESPUÉS de la clase (trabajo asincrónico)
A36: Ítem | D36: Min | E36: Nivel Bloom | F36: Actividad | G36: Entregable | H36: Enlace verificado
A37: D1 | D37: 45 | E37: Aplicar | F37: Entregar el cuaderno con la detección de picos y la comparación ECG frente a PPG. (Google Colab) | G37: Cuaderno con gráficas | H37: https://colab.research.google.com/
A38: D2 | D38: 25 | E38: Evaluar | F38: Escribir cuándo un PPG de muñeca no es confiable y qué alternativas propondrías. (Aula virtual) | G38: Texto de media página | H38: https://physionet.org/content/bidmc/1.0.0/
A39: D3 | D39: 20 | E39: Crear | F39: Proponer una característica nueva para separar latidos normales de arrítmicos. (Foro) | G39: Propuesta en el foro | H39: https://physionet.org/content/mitdb/1.0.0/
C40: Total | D40: =SUM(D37:D39)

Sheet Semana 7
A1: Semana 7: Imágenes médicas: rayos X, TAC, ecografía, resonancia magnética y PET
A2: Sistemas Biomecatrónicos, ESPOL. Clase virtual sincrónica de 1 h 45 min (105 min). Organización por taxonomía de Bloom revisada.
A4: Resultado de aprendizaje | B4: Compara las modalidades de imagen médica según física, contraste, riesgos y aplicaciones, y prepara imágenes para modelos de ML.
A5: Duración total (min) | B5: =D33
A6: Control de tiempo | B6: =IF(D33=105,"Correcto: 105 min","Revisar: no suma 105 min")
A8: 1. Objetivos por nivel de la taxonomía de Bloom
A9: Nivel | E9: Verbo de acción | F9: Objetivo de aprendizaje | G9: Evidencia
A10: 1. Recordar | E10: Enumerar/Definir | F10: Nombrar cinco modalidades de imagen (rayos X, TAC, ecografía, resonancia magnética, PET) y su formato DICOM. | G10: Quiz de 5 preguntas en Google Forms
A11: 2. Comprender | E11: Explicar | F11: Explicar qué mide cada modalidad y qué contraste ofrece. | G11: Explicación breve en foro o mapa conceptual
A12: 3. Aplicar | E12: Aplicar/Ejecutar | F12: Abrir y visualizar un estudio DICOM y ajustar ventana y nivel. | G12: Notebook o ejercicio resuelto en clase
A13: 4. Analizar | E13: Analizar/Comparar | F13: Analizar ventajas y limitaciones de cada modalidad para una patología dada. | G13: Comparación de resultados o casos en sala virtual
A14: 5. Evaluar | E14: Evaluar/Justificar | F14: Evaluar qué modalidad conviene para tumor cerebral, fractura y lesión pulmonar. | G14: Rúbrica de coevaluación de la plenaria
A15: 6. Crear | E15: Diseñar/Proponer | F15: Diseñar un preprocesamiento de imágenes (normalización, recorte, aumento de datos). | G15: Entregable o mini propuesta posterior a la clase
A17: 2. ANTES de la clase (trabajo asincrónico, 48 horas previas)
A18: Ítem | D18: Min | E18: Nivel Bloom | F18: Actividad | G18: Entregable | H18: Enlace verificado
A19: A1 | D19: 30 | E19: Comprender | F19: Leer la descripción de las colecciones de TCIA y elegir una con CT, MRI o PET. (Colecciones de imagen) | G19: Nombre de la colección y modalidad | H19: https://wiki.cancerimagingarchive.net/display/Public/Collections https://www.nature.com/articles/sdata2017124
A20: A2 | D20: 20 | E20: Aplicar | F20: Descargar e instalar 3D Slicer. (Software) | G20: Captura de Slicer abierto | H20: https://www.slicer.org/
A21: A3 | D21: 15 | E21: Recordar | F21: Ver la estructura del conjunto de radiografías de tórax. (Conjunto de datos) | G21: Cantidad de clases e imágenes | H21: https://www.kaggle.com/datasets/paultimothymooney/chest-xray-pneumonia
C22: Total | D22: =SUM(D19:D21)
A24: 3. DURANTE la clase (105 min, paso a paso)
A25: Paso | B25: Inicio (min) | C25: Fin (min) | D25: Min | E25: Fase / Nivel Bloom | F25: Actividad paso a paso | G25: Herramienta | H25: Enlace verificado
A26: 1 | B26: 0 | C26: =B26+D26 | D26: 10 | E26: Apertura (Recordar) | F26: Repaso de señales y objetivos. Pregunta inicial: ¿qué imagen te han hecho o conoces? | G26: Zoom o Teams, chat
A27: 2 | B27: =C26 | C27: =B27+D27 | D27: 20 | E27: Exposición (Comprender) | F27: Exposición: física básica y contraste de rayos X, TAC, ecografía, resonancia magnética y PET; riesgos por radiación; formato DICOM. | G27: Zoom, presentación | H27: https://www.nature.com/articles/sdata2017124
A28: 3 | B28: =C27 | C28: =B28+D28 | D28: 20 | E28: Demostración en vivo (Aplicar) | F28: Demostración en 3D Slicer: cargar un estudio, ajustar ventana y nivel, medir una distancia y observar cortes axial, sagital y coronal. | G28: Zoom, Colab o software | H28: https://www.slicer.org/ https://wiki.cancerimagingarchive.net/display/Public/Collections
A29: 4 | B29: =C28 | C29: =B29+D29 | D29: 5 | E29: Pausa | F29: Pausa de 5 minutos. | G29: Cronómetro visible
A30: 5 | B30: =C29 | C30: =B30+D30 | D30: 25 | E30: Práctica en salas virtuales (Analizar) | F30: Salas de 4 personas: para tres patologías, elegir la modalidad más adecuada y justificar con contraste, riesgo y costo. | G30: Salas de Zoom, Google Docs | H30: https://wiki.cancerimagingarchive.net/display/Public/Collections https://www.kaggle.com/datasets/paultimothymooney/chest-xray-pneumonia
A31: 6 | B31: =C30 | C31: =B31+D31 | D31: 15 | E31: Plenaria y discusión (Evaluar) | F31: Plenaria: cada sala defiende su elección. Discusión sobre acceso a estas tecnologías en hospitales de la región. | G31: Zoom, rúbrica
A32: 7 | B32: =C31 | C32: =B32+D32 | D32: 10 | E32: Cierre y evaluación (Crear) | F32: Quiz en Google Forms, publicación de la tarea y adelanto de la semana 8 (introducción a deep learning). | G32: Google Forms, aula virtual
C33: Total | D33: =SUM(D26:D32)
A35: 4. DESPUÉS de la clase (trabajo asincrónico)
A36: Ítem | D36: Min | E36: Nivel Bloom | F36: Actividad | G36: Entregable | H36: Enlace verificado
A37: D1 | D37: 40 | E37: Analizar | F37: Completar una tabla comparativa de las cinco modalidades (principio físico, contraste, riesgo, uso principal). (Documento de Google) | G37: Tabla completa | H37: https://www.nature.com/articles/sdata2017124
A38: D2 | D38: 30 | E38: Crear | F38: Redactar un plan de preprocesamiento para un conjunto de radiografías. (Aula virtual) | G38: Plan de una página | H38: https://www.kaggle.com/datasets/paultimothymooney/chest-xray-pneumonia
A39: D3 | D39: 20 | E39: Aplicar | F39: Practicar ventana y nivel en 3D Slicer con otro estudio. (3D Slicer) | G39: Captura con dos ventanas distintas | H39: https://www.slicer.org/
C40: Total | D40: =SUM(D37:D39)

Sheet Semana 8
A1: Semana 8: Introducción al deep learning y a las redes neuronales
A2: Sistemas Biomecatrónicos, ESPOL. Clase virtual sincrónica de 1 h 45 min (105 min). Organización por taxonomía de Bloom revisada.
A4: Resultado de aprendizaje | B4: Explica cómo funciona una neurona artificial y una red multicapa, y entrena una red pequeña identificando el efecto de sus hiperparámetros.
A5: Duración total (min) | B5: =D33
A6: Control de tiempo | B6: =IF(D33=105,"Correcto: 105 min","Revisar: no suma 105 min")
A8: 1. Objetivos por nivel de la taxonomía de Bloom
A9: Nivel | E9: Verbo de acción | F9: Objetivo de aprendizaje | G9: Evidencia
A10: 1. Recordar | E10: Enumerar/Definir | F10: Recordar los términos neurona, peso, sesgo, función de activación, capa y época. | G10: Quiz de 5 preguntas en Google Forms
A11: 2. Comprender | E11: Explicar | F11: Explicar el paso hacia adelante y la retropropagación con un ejemplo numérico simple. | G11: Explicación breve en foro o mapa conceptual
A12: 3. Aplicar | E12: Aplicar/Ejecutar | F12: Entrenar una red en TensorFlow Playground y en scikit-learn y observar su aprendizaje. | G12: Notebook o ejercicio resuelto en clase
A13: 4. Analizar | E13: Analizar/Comparar | F13: Analizar el efecto de la tasa de aprendizaje, el número de capas y la activación. | G13: Comparación de resultados o casos en sala virtual
A14: 5. Evaluar | E14: Evaluar/Justificar | F14: Evaluar cuándo una red profunda supera a un modelo clásico. | G14: Rúbrica de coevaluación de la plenaria
A15: 6. Crear | E15: Diseñar/Proponer | F15: Diseñar una arquitectura para un problema biomédico sencillo. | G15: Entregable o mini propuesta posterior a la clase
A17: 2. ANTES de la clase (trabajo asincrónico, 48 horas previas)
A18: Ítem | D18: Min | E18: Nivel Bloom | F18: Actividad | G18: Entregable | H18: Enlace verificado
A19: A1 | D19: 40 | E19: Comprender | F19: Cursar el módulo de redes neuronales del Machine Learning Crash Course. (Curso en línea) | G19: Resumen de cinco líneas | H19: https://developers.google.com/machine-learning/crash-course
A20: A2 | D20: 20 | E20: Aplicar | F20: Jugar 15 minutos con TensorFlow Playground y anotar qué cambia al agregar capas. (Simulador) | G20: Tres observaciones | H20: https://playground.tensorflow.org/
A21: A3 | D21: 20 | E21: Comprender | F21: Leer la sección de perceptrón multicapa de scikit-learn. (Guía de usuario) | G21: Fórmula de la neurona escrita a mano | H21: https://scikit-learn.org/stable/modules/neural_networks_supervised.html
C22: Total | D22: =SUM(D19:D21)
A24: 3. DURANTE la clase (105 min, paso a paso)
A25: Paso | B25: Inicio (min) | C25: Fin (min) | D25: Min | E25: Fase / Nivel Bloom | F25: Actividad paso a paso | G25: Herramienta | H25: Enlace verificado
A26: 1 | B26: 0 | C26: =B26+D26 | D26: 10 | E26: Apertura (Recordar) | F26: Repaso de imágenes médicas y de la tarea. Agenda: neurona, capa, entrenamiento. | G26: Zoom o Teams, chat | H26: https://developers.google.com/machine-learning/crash-course
A27: 2 | B27: =C26 | C27: =B27+D27 | D27: 20 | E27: Exposición (Comprender) | F27: Exposición: neurona artificial, funciones de activación, red multicapa, función de pérdida, descenso del gradiente y retropropagación con un ejemplo numérico. | G27: Zoom, presentación | H27: https://developers.google.com/machine-learning/crash-course
A28: 3 | B28: =C27 | C28: =B28+D28 | D28: 20 | E28: Demostración en vivo (Aplicar) | F28: Demostración en TensorFlow Playground: clasificar un conjunto de espirales cambiando capas, neuronas y tasa de aprendizaje. | G28: Zoom, Colab o software | H28: https://playground.tensorflow.org/
A29: 4 | B29: =C28 | C29: =B29+D29 | D29: 5 | E29: Pausa | F29: Pausa de 5 minutos. | G29: Cronómetro visible
A30: 5 | B30: =C29 | C30: =B30+D30 | D30: 25 | E30: Práctica en salas virtuales (Analizar) | F30: Salas de 4 personas: en Playground, encontrar la red mínima que clasifique el conjunto de espirales y explicar por qué funciona. | G30: Salas de Zoom, Google Docs | H30: https://playground.tensorflow.org/
A31: 6 | B31: =C30 | C31: =B31+D31 | D31: 15 | E31: Plenaria y discusión (Evaluar) | F31: Plenaria: cada sala muestra su arquitectura. Discusión sobre sobreajuste y sobre el costo de datos y cómputo. | G31: Zoom, rúbrica
A32: 7 | B32: =C31 | C32: =B32+D32 | D32: 10 | E32: Cierre y evaluación (Crear) | F32: Quiz en Google Forms, publicación de la tarea y adelanto de la semana 9 (redes neuronales en señales). | G32: Google Forms, aula virtual
C33: Total | D33: =SUM(D26:D32)
A35: 4. DESPUÉS de la clase (trabajo asincrónico)
A36: Ítem | D36: Min | E36: Nivel Bloom | F36: Actividad | G36: Entregable | H36: Enlace verificado
A37: D1 | D37: 45 | E37: Aplicar | F37: Entrenar una red multicapa de scikit-learn en un conjunto tabular y comparar con k-vecinos. (Google Colab) | G37: Cuaderno con tabla de comparación | H37: https://scikit-learn.org/stable/modules/neural_networks_supervised.html https://colab.research.google.com/
A38: D2 | D38: 25 | E38: Evaluar | F38: Escribir cuándo usarías una red profunda y cuándo un modelo clásico. (Aula virtual) | G38: Texto de media página | H38: https://developers.google.com/machine-learning/crash-course
A39: D3 | D39: 20 | E39: Crear | F39: Dibujar una arquitectura de red para clasificar latidos de ECG. (Documento de Google) | G39: Diagrama con dimensiones de cada capa
C40: Total | D40: =SUM(D37:D39)

Sheet Semana 9
A1: Semana 9: Redes neuronales aplicadas a señales biomédicas
A2: Sistemas Biomecatrónicos, ESPOL. Clase virtual sincrónica de 1 h 45 min (105 min). Organización por taxonomía de Bloom revisada.
A4: Resultado de aprendizaje | B4: Entrena y evalúa una red neuronal multicapa para clasificar latidos de ECG o gestos de EMG, controlando el sobreajuste.
A5: Duración total (min) | B5: =D33
A6: Control de tiempo | B6: =IF(D33=105,"Correcto: 105 min","Revisar: no suma 105 min")
A8: 1. Objetivos por nivel de la taxonomía de Bloom
A9: Nivel | E9: Verbo de acción | F9: Objetivo de aprendizaje | G9: Evidencia
A10: 1. Recordar | E10: Enumerar/Definir | F10: Recordar los conceptos de regularización, dropout y detención temprana. | G10: Quiz de 5 preguntas en Google Forms
A11: 2. Comprender | E11: Explicar | F11: Explicar por qué se normalizan las entradas y cómo se codifican las clases. | G11: Explicación breve en foro o mapa conceptual
A12: 3. Aplicar | E12: Aplicar/Ejecutar | F12: Entrenar una red multicapa con las características de la semana 5 o 6. | G12: Notebook o ejercicio resuelto en clase
A13: 4. Analizar | E13: Analizar/Comparar | F13: Analizar las curvas de pérdida para detectar sobreajuste y subajuste. | G13: Comparación de resultados o casos en sala virtual
A14: 5. Evaluar | E14: Evaluar/Justificar | F14: Evaluar el modelo con sensibilidad, especificidad y validación cruzada. | G14: Rúbrica de coevaluación de la plenaria
A15: 6. Crear | E15: Diseñar/Proponer | F15: Mejorar la red con regularización y comparar antes y después. | G15: Entregable o mini propuesta posterior a la clase
A17: 2. ANTES de la clase (trabajo asincrónico, 48 horas previas)
A18: Ítem | D18: Min | E18: Nivel Bloom | F18: Actividad | G18: Entregable | H18: Enlace verificado
A19: A1 | D19: 30 | E19: Aplicar | F19: Repasar el cuaderno de ECG o EMG y preparar la matriz de características. (Google Colab) | G19: Matriz de características lista | H19: https://colab.research.google.com/
A20: A2 | D20: 25 | E20: Comprender | F20: Leer la sección de redes neuronales de scikit-learn sobre regularización. (Guía de usuario) | G20: Definición de regularización | H20: https://scikit-learn.org/stable/modules/neural_networks_supervised.html
A21: A3 | D21: 15 | E21: Recordar | F21: Revisar el conjunto MIT-BIH y decidir cuáles clases de latido usar. (Conjunto de datos) | G21: Lista de clases elegidas | H21: https://physionet.org/content/mitdb/1.0.0/
C22: Total | D22: =SUM(D19:D21)
A24: 3. DURANTE la clase (105 min, paso a paso)
A25: Paso | B25: Inicio (min) | C25: Fin (min) | D25: Min | E25: Fase / Nivel Bloom | F25: Actividad paso a paso | G25: Herramienta | H25: Enlace verificado
A26: 1 | B26: 0 | C26: =B26+D26 | D26: 10 | E26: Apertura (Recordar) | F26: Repaso del entrenamiento de una red y de las tareas. Objetivo: red multicapa sobre señales reales. | G26: Zoom o Teams, chat | H26: https://scikit-learn.org/stable/modules/neural_networks_supervised.html
A27: 2 | B27: =C26 | C27: =B27+D27 | D27: 20 | E27: Exposición (Comprender) | F27: Exposición: preparación de entradas, arquitectura, regularización, detención temprana y curvas de aprendizaje. Métricas clínicas. | G27: Zoom, presentación | H27: https://scikit-learn.org/stable/modules/neural_networks_supervised.html
A28: 3 | B28: =C27 | C28: =B28+D28 | D28: 20 | E28: Demostración en vivo (Aplicar) | F28: Demostración en Colab: entrenar una red multicapa con características de ECG y graficar la pérdida en entrenamiento y validación. | G28: Zoom, Colab o software | H28: https://colab.research.google.com/ https://physionet.org/content/mitdb/1.0.0/
A29: 4 | B29: =C28 | C29: =B29+D29 | D29: 5 | E29: Pausa | F29: Pausa de 5 minutos. | G29: Cronómetro visible
A30: 5 | B30: =C29 | C30: =B30+D30 | D30: 25 | E30: Práctica en salas virtuales (Analizar) | F30: Salas de 4 personas: agregar regularización o detención temprana y comparar métricas antes y después del cambio. | G30: Salas de Zoom, Google Docs | H30: https://physionet.org/content/mitdb/1.0.0/ https://archive.ics.uci.edu/dataset/278/emg+dataset+in+lower+limb
A31: 6 | B31: =C30 | C31: =B31+D31 | D31: 15 | E31: Plenaria y discusión (Evaluar) | F31: Plenaria: cada sala presenta su mejora. Discusión sobre datos desbalanceados y sobre por qué la exactitud engaña. | G31: Zoom, rúbrica
A32: 7 | B32: =C31 | C32: =B32+D32 | D32: 10 | E32: Cierre y evaluación (Crear) | F32: Quiz en Google Forms, publicación de la tarea y adelanto de la semana 10 (redes convolucionales). | G32: Google Forms, aula virtual
C33: Total | D33: =SUM(D26:D32)
A35: 4. DESPUÉS de la clase (trabajo asincrónico)
A36: Ítem | D36: Min | E36: Nivel Bloom | F36: Actividad | G36: Entregable | H36: Enlace verificado
A37: D1 | D37: 50 | E37: Aplicar | F37: Entregar el cuaderno con la red, las curvas de pérdida y las métricas clínicas. (Google Colab) | G37: Cuaderno con gráficas | H37: https://colab.research.google.com/
A38: D2 | D38: 20 | E38: Analizar | F38: Redactar qué falló primero al entrenar y cómo lo resolviste. (Aula virtual) | G38: Texto de media página
A39: D3 | D39: 20 | E39: Crear | F39: Proponer cómo manejarías las clases desbalanceadas en un hospital. (Foro) | G39: Propuesta en el foro | H39: https://physionet.org/content/mitdb/1.0.0/
C40: Total | D40: =SUM(D37:D39)

Sheet Semana 10
A1: Semana 10: Redes neuronales convolucionales (CNN)
A2: Sistemas Biomecatrónicos, ESPOL. Clase virtual sincrónica de 1 h 45 min (105 min). Organización por taxonomía de Bloom revisada.
A4: Resultado de aprendizaje | B4: Explica las capas de una CNN (convolución, activación, pooling, capa densa) y entrena una CNN pequeña sobre imágenes.
A5: Duración total (min) | B5: =D33
A6: Control de tiempo | B6: =IF(D33=105,"Correcto: 105 min","Revisar: no suma 105 min")
A8: 1. Objetivos por nivel de la taxonomía de Bloom
A9: Nivel | E9: Verbo de acción | F9: Objetivo de aprendizaje | G9: Evidencia
A10: 1. Recordar | E10: Enumerar/Definir | F10: Nombrar las capas de una CNN y el papel de cada una. | G10: Quiz de 5 preguntas en Google Forms
A11: 2. Comprender | E11: Explicar | F11: Explicar cómo un filtro convolucional detecta bordes y patrones. | G11: Explicación breve en foro o mapa conceptual
A12: 3. Aplicar | E12: Aplicar/Ejecutar | F12: Construir y entrenar una CNN pequeña en Colab con Keras. | G12: Notebook o ejercicio resuelto en clase
A13: 4. Analizar | E13: Analizar/Comparar | F13: Analizar cómo cambian los mapas de características entre capas. | G13: Comparación de resultados o casos en sala virtual
A14: 5. Evaluar | E14: Evaluar/Justificar | F14: Evaluar el número de filtros y de capas frente a la exactitud y al costo de cómputo. | G14: Rúbrica de coevaluación de la plenaria
A15: 6. Crear | E15: Diseñar/Proponer | F15: Diseñar una CNN para radiografías de tórax. | G15: Entregable o mini propuesta posterior a la clase
A17: 2. ANTES de la clase (trabajo asincrónico, 48 horas previas)
A18: Ítem | D18: Min | E18: Nivel Bloom | F18: Actividad | G18: Entregable | H18: Enlace verificado
A19: A1 | D19: 40 | E19: Comprender | F19: Leer las notas de CS231n sobre CNN hasta la sección de capas de pooling. (Notas del curso) | G19: Esquema de una CNN con dimensiones | H19: https://cs231n.github.io/convolutional-networks/
A20: A2 | D20: 30 | E20: Comprender | F20: Leer el tutorial de CNN de TensorFlow. (Tutorial) | G20: Dos preguntas sobre el código | H20: https://www.tensorflow.org/tutorials/images/cnn
A21: A3 | D21: 10 | E21: Aplicar | F21: Activar la GPU en Colab y ejecutar la celda de prueba. (Google Colab) | G21: Captura de la GPU activa | H21: https://colab.research.google.com/
C22: Total | D22: =SUM(D19:D21)
A24: 3. DURANTE la clase (105 min, paso a paso)
A25: Paso | B25: Inicio (min) | C25: Fin (min) | D25: Min | E25: Fase / Nivel Bloom | F25: Actividad paso a paso | G25: Herramienta | H25: Enlace verificado
A26: 1 | B26: 0 | C26: =B26+D26 | D26: 10 | E26: Apertura (Recordar) | F26: Repaso de redes multicapa y de la tarea. Pregunta: ¿por qué una red densa es mala para imágenes? | G26: Zoom o Teams, chat | H26: https://cs231n.github.io/convolutional-networks/
A27: 2 | B27: =C26 | C27: =B27+D27 | D27: 20 | E27: Exposición (Comprender) | F27: Exposición: convolución, filtros, mapas de características, pooling, capas densas, receptive field y parámetros. | G27: Zoom, presentación | H27: https://cs231n.github.io/convolutional-networks/
A28: 3 | B28: =C27 | C28: =B28+D28 | D28: 20 | E28: Demostración en vivo (Aplicar) | F28: Demostración en Colab: construir la CNN del tutorial, entrenarla y visualizar los mapas de características de una capa. | G28: Zoom, Colab o software | H28: https://www.tensorflow.org/tutorials/images/cnn https://colab.research.google.com/
A29: 4 | B29: =C28 | C29: =B29+D29 | D29: 5 | E29: Pausa | F29: Pausa de 5 minutos. | G29: Cronómetro visible
A30: 5 | B30: =C29 | C30: =B30+D30 | D30: 25 | E30: Práctica en salas virtuales (Analizar) | F30: Salas de 4 personas: variar filtros y capas, registrar exactitud y tiempo de entrenamiento y explicar la relación. | G30: Salas de Zoom, Google Docs | H30: https://www.tensorflow.org/tutorials/images/cnn
A31: 6 | B31: =C30 | C31: =B31+D31 | D31: 15 | E31: Plenaria y discusión (Evaluar) | F31: Plenaria: cada sala presenta su configuración. Discusión sobre datos etiquetados escasos en medicina. | G31: Zoom, rúbrica
A32: 7 | B32: =C31 | C32: =B32+D32 | D32: 10 | E32: Cierre y evaluación (Crear) | F32: Quiz en Google Forms, publicación de la tarea y adelanto de la semana 11 (clasificación de tumores y patologías). | G32: Google Forms, aula virtual
C33: Total | D33: =SUM(D26:D32)
A35: 4. DESPUÉS de la clase (trabajo asincrónico)
A36: Ítem | D36: Min | E36: Nivel Bloom | F36: Actividad | G36: Entregable | H36: Enlace verificado
A37: D1 | D37: 45 | E37: Aplicar | F37: Entrenar la CNN con dos configuraciones y comparar exactitud y parámetros. (Google Colab) | G37: Cuaderno con tabla comparativa | H37: https://www.tensorflow.org/tutorials/images/cnn https://colab.research.google.com/
A38: D2 | D38: 25 | E38: Analizar | F38: Explicar en un párrafo qué aprende la primera y la última capa convolucional. (Aula virtual) | G38: Párrafo con dos ejemplos | H38: https://cs231n.github.io/convolutional-networks/
A39: D3 | D39: 25 | E39: Crear | F39: Dibujar una arquitectura CNN para radiografías de tórax con dimensiones de entrada y salida. (Documento de Google) | G39: Diagrama de arquitectura | H39: https://www.kaggle.com/datasets/paultimothymooney/chest-xray-pneumonia
C40: Total | D40: =SUM(D37:D39)

Sheet Semana 11
A1: Semana 11: Clasificación de tumores y patologías con redes convolucionales
A2: Sistemas Biomecatrónicos, ESPOL. Clase virtual sincrónica de 1 h 45 min (105 min). Organización por taxonomía de Bloom revisada.
A4: Resultado de aprendizaje | B4: Entrena y evalúa una CNN para clasificar imágenes médicas (radiografía de tórax) y explica su desempeño con métricas clínicas.
A5: Duración total (min) | B5: =D33
A6: Control de tiempo | B6: =IF(D33=105,"Correcto: 105 min","Revisar: no suma 105 min")
A8: 1. Objetivos por nivel de la taxonomía de Bloom
A9: Nivel | E9: Verbo de acción | F9: Objetivo de aprendizaje | G9: Evidencia
A10: 1. Recordar | E10: Enumerar/Definir | F10: Recordar la matriz de confusión, sensibilidad, especificidad y curva ROC. | G10: Quiz de 5 preguntas en Google Forms
A11: 2. Comprender | E11: Explicar | F11: Explicar qué es aprendizaje por transferencia y por qué se usa en medicina. | G11: Explicación breve en foro o mapa conceptual
A12: 3. Aplicar | E12: Aplicar/Ejecutar | F12: Entrenar una CNN para distinguir radiografías normales de neumonía. | G12: Notebook o ejercicio resuelto en clase
A13: 4. Analizar | E13: Analizar/Comparar | F13: Analizar los falsos negativos y el efecto del desbalance de clases. | G13: Comparación de resultados o casos en sala virtual
A14: 5. Evaluar | E14: Evaluar/Justificar | F14: Evaluar si el modelo es seguro para uso clínico y qué validaciones faltan. | G14: Rúbrica de coevaluación de la plenaria
A15: 6. Crear | E15: Diseñar/Proponer | F15: Crear un plan de validación para llevar el modelo a un hospital. | G15: Entregable o mini propuesta posterior a la clase
A17: 2. ANTES de la clase (trabajo asincrónico, 48 horas previas)
A18: Ítem | D18: Min | E18: Nivel Bloom | F18: Actividad | G18: Entregable | H18: Enlace verificado
A19: A1 | D19: 25 | E19: Comprender | F19: Explorar el conjunto de radiografías de tórax y contar imágenes por clase. (Conjunto de datos) | G19: Tabla de imágenes por clase | H19: https://www.kaggle.com/datasets/paultimothymooney/chest-xray-pneumonia
A20: A2 | D20: 30 | E20: Recordar | F20: Repasar el tutorial de CNN y las métricas clínicas. (Tutorial) | G20: Definiciones de sensibilidad y AUC | H20: https://www.tensorflow.org/tutorials/images/cnn https://scikit-learn.org/stable/user_guide.html
A21: A3 | D21: 20 | E21: Comprender | F21: Revisar una colección de TCIA con tumores y anotar la modalidad. (Colecciones de imagen) | G21: Colección y modalidad | H21: https://wiki.cancerimagingarchive.net/display/Public/Collections
C22: Total | D22: =SUM(D19:D21)
A24: 3. DURANTE la clase (105 min, paso a paso)
A25: Paso | B25: Inicio (min) | C25: Fin (min) | D25: Min | E25: Fase / Nivel Bloom | F25: Actividad paso a paso | G25: Herramienta | H25: Enlace verificado
A26: 1 | B26: 0 | C26: =B26+D26 | D26: 10 | E26: Apertura (Recordar) | F26: Repaso de CNN y de la tarea. Objetivo: llevar una CNN a un problema clínico real. | G26: Zoom o Teams, chat | H26: https://www.kaggle.com/datasets/paultimothymooney/chest-xray-pneumonia
